Workbook

Sheet Raw_Ticket_Data
A1: Request Recieved | B1: Commitment | C1: Assignee | D1: Task Type | E1: Priority | F1: Ticket # | G1: Summary | H1: Status | I1: Start Date | J1: ETA | K1: Closed Date | L1: Sprint | M1: Notes | N1: Cycle Time (Days) | O1: Forecast Accuracy (ETA)
A2: Before | B2: Committed | C2: Dev 3 | D2: Support Task | E2: P2 (High) | F2: EXP-1023 | G2: Fix deployment failure in staging pipeline | H2: New | L2: =IF(K2="","",IF(AND(K2>=DATE(2025,10,21),K2<=DATE(2025,10,21)),"PI-3 Sprint 6",IF(AND(K2>=DATE(2025,10,22),K2<=DATE(2025,11,4)),"Sprint 1",IF(AND(K2>=DATE(2025,11,5),K2<=DATE(2025,11,18)),"Sprint 2",IF(AND(K2>=DATE(2025,11,19),K2<=DATE(2025,12,2)),"Sprint 3",IF(AND(K2>=DATE(2025,12,3),K2<=DATE(2025,12,16)),"Sprint 4",IF(AND(K2>=DATE(2025,12,17),K2<=DATE(2025,12,30)),"Sprint 5",IF(AND(K2>=DATE(2025,12,31),K2<=DATE(2026,1,20)),"Sprint 6","N/A")))))))) | N2: =IF(K2="", "", (K2 - I2 +1)) | O2: =IF(K2="","", IF(J2="", "N/A", IF(K2 > J2, "Late", IF(K2 < J2, "Early", IF(K2 = J2, "On time", "")))))
A3: Before | B3: Committed | C3: Dev 5 | D3: Task | E3: P3 (Med) | F3: EXP-1047 | G3: Update Terraform module for S3 encryption | H3: Closed | I3: 45952 | J3: 45966 | K3: 45967 | L3: =IF(K3="","",IF(AND(K3>=DATE(2025,10,21),K3<=DATE(2025,10,21)),"PI-3 Sprint 6",IF(AND(K3>=DATE(2025,10,22),K3<=DATE(2025,11,4)),"Sprint 1",IF(AND(K3>=DATE(2025,11,5),K3<=DATE(2025,11,18)),"Sprint 2",IF(AND(K3>=DATE(2025,11,19),K3<=DATE(2025,12,2)),"Sprint 3",IF(AND(K3>=DATE(2025,12,3),K3<=DATE(2025,12,16)),"Sprint 4",IF(AND(K3>=DATE(2025,12,17),K3<=DATE(2025,12,30)),"Sprint 5",IF(AND(K3>=DATE(2025,12,31),K3<=DATE(2026,1,20)),"Sprint 6","N/A")))))))) -> Sprint 2 | N3: =IF(K3="", "", (K3 - I3 +1)) -> 16 | O3: =IF(K3="","", IF(J3="", "N/A", IF(K3 > J3, "Late", IF(K3 < J3, "Early", IF(K3 = J3, "On time", ""))))) -> Late
A4: Before | B4: Committed | C4: Dev 1 | D4: Task | E4: P4 (Low) | F4: EXP-1091 | G4: Investigate intermittent API timeout errors | H4: Closed | I4: 45953 | J4: 45965 | K4: 45965 | L4: =IF(K4="","",IF(AND(K4>=DATE(2025,10,21),K4<=DATE(2025,10,21)),"PI-3 Sprint 6",IF(AND(K4>=DATE(2025,10,22),K4<=DATE(2025,11,4)),"Sprint 1",IF(AND(K4>=DATE(2025,11,5),K4<=DATE(2025,11,18)),"Sprint 2",IF(AND(K4>=DATE(2025,11,19),K4<=DATE(2025,12,2)),"Sprint 3",IF(AND(K4>=DATE(2025,12,3),K4<=DATE(2025,12,16)),"Sprint 4",IF(AND(K4>=DATE(2025,12,17),K4<=DATE(2025,12,30)),"Sprint 5",IF(AND(K4>=DATE(2025,12,31),K4<=DATE(2026,1,20)),"Sprint 6","N/A")))))))) -> Sprint 1 | N4: =IF(K4="", "", (K4 - I4 +1)) -> 13 | O4: =IF(K4="","", IF(J4="", "N/A", IF(K4 > J4, "Late", IF(K4 < J4, "Early", IF(K4 = J4, "On time", ""))))) -> On time
A5: Before | B5: Committed | C5: Dev 2 | D5: Task | E5: P1 (Critical) | F5: EXP-1112 | G5: Rotate expired service account credentials | H5: Closed | I5: 45952 | J5: 45966 | K5: 45966 | L5: =IF(K5="","",IF(AND(K5>=DATE(2025,10,21),K5<=DATE(2025,10,21)),"PI-3 Sprint 6",IF(AND(K5>=DATE(2025,10,22),K5<=DATE(2025,11,4)),"Sprint 1",IF(AND(K5>=DATE(2025,11,5),K5<=DATE(2025,11,18)),"Sprint 2",IF(AND(K5>=DATE(2025,11,19),K5<=DATE(2025,12,2)),"Sprint 3",IF(AND(K5>=DATE(2025,12,3),K5<=DATE(2025,12,16)),"Sprint 4",IF(AND(K5>=DATE(2025,12,17),K5<=DATE(2025,12,30)),"Sprint 5",IF(AND(K5>=DATE(2025,12,31),K5<=DATE(2026,1,20)),"Sprint 6","N/A")))))))) -> Sprint 2 | N5: =IF(K5="", "", (K5 - I5 +1)) -> 15 | O5: =IF(K5="","", IF(J5="", "N/A", IF(K5 > J5, "Late", IF(K5 < J5, "Early", IF(K5 = J5, "On time", ""))))) -> On time
A6: Before | B6: Committed | C6: Dev 4 | D6: Task | E6: P3 (Med) | F6: EXP-1138 | G6: Enable logging for failed Lambda executions | H6: New | L6: =IF(K6="","",IF(AND(K6>=DATE(2025,10,21),K6<=DATE(2025,10,21)),"PI-3 Sprint 6",IF(AND(K6>=DATE(2025,10,22),K6<=DATE(2025,11,4)),"Sprint 1",IF(AND(K6>=DATE(2025,11,5),K6<=DATE(2025,11,18)),"Sprint 2",IF(AND(K6>=DATE(2025,11,19),K6<=DATE(2025,12,2)),"Sprint 3",IF(AND(K6>=DATE(2025,12,3),K6<=DATE(2025,12,16)),"Sprint 4",IF(AND(K6>=DATE(2025,12,17),K6<=DATE(2025,12,30)),"Sprint 5",IF(AND(K6>=DATE(2025,12,31),K6<=DATE(2026,1,20)),"Sprint 6","N/A")))))))) | N6: =IF(K6="", "", (K6 - I6 +1)) | O6: =IF(K6="","", IF(J6="", "N/A", IF(K6 > J6, "Late", IF(K6 < J6, "Early", IF(K6 = J6, "On time", "")))))
A7: Before | B7: Committed | C7: Dev 2 | D7: Task | E7: P2 (High) | F7: EXP-1184 | G7: Clean up unused feature flags | H7: Closed | I7: 45961 | J7: 45965 | K7: 45965 | L7: =IF(K7="","",IF(AND(K7>=DATE(2025,10,21),K7<=DATE(2025,10,21)),"PI-3 Sprint 6",IF(AND(K7>=DATE(2025,10,22),K7<=DATE(2025,11,4)),"Sprint 1",IF(AND(K7>=DATE(2025,11,5),K7<=DATE(2025,11,18)),"Sprint 2",IF(AND(K7>=DATE(2025,11,19),K7<=DATE(2025,12,2)),"Sprint 3",IF(AND(K7>=DATE(2025,12,3),K7<=DATE(2025,12,16)),"Sprint 4",IF(AND(K7>=DATE(2025,12,17),K7<=DATE(2025,12,30)),"Sprint 5",IF(AND(K7>=DATE(2025,12,31),K7<=DATE(2026,1,20)),"Sprint 6","N/A")))))))) -> Sprint 1 | N7: =IF(K7="", "", (K7 - I7 +1)) -> 5 | O7: =IF(K7="","", IF(J7="", "N/A", IF(K7 > J7, "Late", IF(K7 < J7, "Early", IF(K7 = J7, "On time", ""))))) -> On time
A8: Before | B8: Committed | C8: Dev 4 | D8: Task | E8: P4 (Low) | F8: EXP-1219 | G8: Update CI runner to latest image version | H8: Closed | I8: 45953 | J8: 45964 | K8: 45963 | L8: =IF(K8="","",IF(AND(K8>=DATE(2025,10,21),K8<=DATE(2025,10,21)),"PI-3 Sprint 6",IF(AND(K8>=DATE(2025,10,22),K8<=DATE(2025,11,4)),"Sprint 1",IF(AND(K8>=DATE(2025,11,5),K8<=DATE(2025,11,18)),"Sprint 2",IF(AND(K8>=DATE(2025,11,19),K8<=DATE(2025,12,2)),"Sprint 3",IF(AND(K8>=DATE(2025,12,3),K8<=DATE(2025,12,16)),"Sprint 4",IF(AND(K8>=DATE(2025,12,17),K8<=DATE(2025,12,30)),"Sprint 5",IF(AND(K8>=DATE(2025,12,31),K8<=DATE(2026,1,20)),"Sprint 6","N/A")))))))) -> Sprint 1 | N8: =IF(K8="", "", (K8 - I8 +1)) -> 11 | O8: =IF(K8="","", IF(J8="", "N/A", IF(K8 > J8, "Late", IF(K8 < J8, "Early", IF(K8 = J8, "On time", ""))))) -> Early
A9: Before | B9: Committed | C9: Dev 3 | D9: Support Task | E9: P2 (High) | F9: EXP-1245 | G9: Fix broken link in internal runbook | H9: Closed | I9: 45955 | J9: 45960 | K9: 45960 | L9: =IF(K9="","",IF(AND(K9>=DATE(2025,10,21),K9<=DATE(2025,10,21)),"PI-3 Sprint 6",IF(AND(K9>=DATE(2025,10,22),K9<=DATE(2025,11,4)),"Sprint 1",IF(AND(K9>=DATE(2025,11,5),K9<=DATE(2025,11,18)),"Sprint 2",IF(AND(K9>=DATE(2025,11,19),K9<=DATE(2025,12,2)),"Sprint 3",IF(AND(K9>=DATE(2025,12,3),K9<=DATE(2025,12,16)),"Sprint 4",IF(AND(K9>=DATE(2025,12,17),K9<=DATE(2025,12,30)),"Sprint 5",IF(AND(K9>=DATE(2025,12,31),K9<=DATE(2026,1,20)),"Sprint 6","N/A")))))))) -> Sprint 1 | N9: =IF(K9="", "", (K9 - I9 +1)) -> 6 | O9: =IF(K9="","", IF(J9="", "N/A", IF(K9 > J9, "Late", IF(K9 < J9, "Early", IF(K9 = J9, "On time", ""))))) -> On time
A10: Before | B10: Committed | C10: Dev 1 | D10: Task | E10: P1 (Critical) | F10: EXP-1277 | G10: Investigate high memory usage on prod node | H10: New | L10: =IF(K10="","",IF(AND(K10>=DATE(2025,10,21),K10<=DATE(2025,10,21)),"PI-3 Sprint 6",IF(AND(K10>=DATE(2025,10,22),K10<=DATE(2025,11,4)),"Sprint 1",IF(AND(K10>=DATE(2025,11,5),K10<=DATE(2025,11,18)),"Sprint 2",IF(AND(K10>=DATE(2025,11,19),K10<=DATE(2025,12,2)),"Sprint 3",IF(AND(K10>=DATE(2025,12,3),K10<=DATE(2025,12,16)),"Sprint 4",IF(AND(K10>=DATE(2025,12,17),K10<=DATE(2025,12,30)),"Sprint 5",IF(AND(K10>=DATE(2025,12,31),K10<=DATE(2026,1,20)),"Sprint 6","N/A")))))))) | N10: =IF(K10="", "", (K10 - I10 +1)) | O10: =IF(K10="","", IF(J10="", "N/A", IF(K10 > J10, "Late", IF(K10 < J10, "Early", IF(K10 = J10, "On time", "")))))
A11: Before | B11: Committed | C11: Dev 5 | D11: Task | E11: P3 (Med) | F11: EXP-1296 | G11: Add alert for failed nightly batch job | H11: Closed | I11: 45952 | J11: 45963 | K11: 45963 | L11: =IF(K11="","",IF(AND(K11>=DATE(2025,10,21),K11<=DATE(2025,10,21)),"PI-3 Sprint 6",IF(AND(K11>=DATE(2025,10,22),K11<=DATE(2025,11,4)),"Sprint 1",IF(AND(K11>=DATE(2025,11,5),K11<=DATE(2025,11,18)),"Sprint 2",IF(AND(K11>=DATE(2025,11,19),K11<=DATE(2025,12,2)),"Sprint 3",IF(AND(K11>=DATE(2025,12,3),K11<=DATE(2025,12,16)),"Sprint 4",IF(AND(K11>=DATE(2025,12,17),K11<=DATE(2025,12,30)),"Sprint 5",IF(AND(K11>=DATE(2025,12,31),K11<=DATE(2026,1,20)),"Sprint 6","N/A")))))))) -> Sprint 1 | N11: =IF(K11="", "", (K11 - I11 +1)) -> 12 | O11: =IF(K11="","", IF(J11="", "N/A", IF(K11 > J11, "Late", IF(K11 < J11, "Early", IF(K11 = J11, "On time", ""))))) -> On time
A12: Before | B12: Committed | C12: Dev 1 | D12: Task | E12: P4 (Low) | F12: EXP-1321 | G12: Upgrade Kubernetes cluster minor version | H12: Closed | I12: 45958 | J12: 45963 | K12: 45963 | L12: =IF(K12="","",IF(AND(K12>=DATE(2025,10,21),K12<=DATE(2025,10,21)),"PI-3 Sprint 6",IF(AND(K12>=DATE(2025,10,22),K12<=DATE(2025,11,4)),"Sprint 1",IF(AND(K12>=DATE(2025,11,5),K12<=DATE(2025,11,18)),"Sprint 2",IF(AND(K12>=DATE(2025,11,19),K12<=DATE(2025,12,2)),"Sprint 3",IF(AND(K12>=DATE(2025,12,3),K12<=DATE(2025,12,16)),"Sprint 4",IF(AND(K12>=DATE(2025,12,17),K12<=DATE(2025,12,30)),"Sprint 5",IF(AND(K12>=DATE(2025,12,31),K12<=DATE(2026,1,20)),"Sprint 6","N/A")))))))) -> Sprint 1 | N12: =IF(K12="", "", (K12 - I12 +1)) -> 6 | O12: =IF(K12="","", IF(J12="", "N/A", IF(K12 > J12, "Late", IF(K12 < J12, "Early", IF(K12 = J12, "On time", ""))))) -> On time
A13: Before | B13: Committed | C13: Dev 3 | D13: Task | E13: P2 (High) | F13: EXP-1350 | G13: Resolve permission issue with secrets manager | H13: On Hold | I13: 45959 | J13: 45975 | L13: =IF(K13="","",IF(AND(K13>=DATE(2025,10,21),K13<=DATE(2025,10,21)),"PI-3 Sprint 6",IF(AND(K13>=DATE(2025,10,22),K13<=DATE(2025,11,4)),"Sprint 1",IF(AND(K13>=DATE(2025,11,5),K13<=DATE(2025,11,18)),"Sprint 2",IF(AND(K13>=DATE(2025,11,19),K13<=DATE(2025,12,2)),"Sprint 3",IF(AND(K13>=DATE(2025,12,3),K13<=DATE(2025,12,16)),"Sprint 4",IF(AND(K13>=DATE(2025,12,17),K13<=DATE(2025,12,30)),"Sprint 5",IF(AND(K13>=DATE(2025,12,31),K13<=DATE(2026,1,20)),"Sprint 6","N/A")))))))) | M13: Pending external dependency | N13: =IF(K13="", "", (K13 - I13 +1)) | O13: =IF(K13="","", IF(J13="", "N/A", IF(K13 > J13, "Late", IF(K13 < J13, "Early", IF(K13 = J13, "On time", "")))))
A14: Before | B14: Uncommitted | C14: Dev 4 | D14: Support Task | E14: P3 (Med) | F14: EXP-1389 | G14: Document rollback steps for payment service | H14: Closed | I14: 45960 | J14: 45979 | K14: 45976 | L14: =IF(K14="","",IF(AND(K14>=DATE(2025,10,21),K14<=DATE(2025,10,21)),"PI-3 Sprint 6",IF(AND(K14>=DATE(2025,10,22),K14<=DATE(2025,11,4)),"Sprint 1",IF(AND(K14>=DATE(2025,11,5),K14<=DATE(2025,11,18)),"Sprint 2",IF(AND(K14>=DATE(2025,11,19),K14<=DATE(2025,12,2)),"Sprint 3",IF(AND(K14>=DATE(2025,12,3),K14<=DATE(2025,12,16)),"Sprint 4",IF(AND(K14>=DATE(2025,12,17),K14<=DATE(2025,12,30)),"Sprint 5",IF(AND(K14>=DATE(2025,12,31),K14<=DATE(2026,1,20)),"Sprint 6","N/A")))))))) -> Sprint 2 | N14: =IF(K14="", "", (K14 - I14 +1)) -> 17 | O14: =IF(K14="","", IF(J14="", "N/A", IF(K14 > J14, "Late", IF(K14 < J14, "Early", IF(K14 = J14, "On time", ""))))) -> Early
A15: Before | B15: Uncommitted | C15: Dev 5 | D15: Support Task | E15: P1 (Critical) | F15: EXP-1413 | G15: Fix flaky integration test in CI | H15: Closed | I15: 45961 | J15: 45980 | K15: 45980 | L15: =IF(K15="","",IF(AND(K15>=DATE(2025,10,21),K15<=DATE(2025,10,21)),"PI-3 Sprint 6",IF(AND(K15>=DATE(2025,10,22),K15<=DATE(2025,11,4)),"Sprint 1",IF(AND(K15>=DATE(2025,11,5),K15<=DATE(2025,11,18)),"Sprint 2",IF(AND(K15>=DATE(2025,11,19),K15<=DATE(2025,12,2)),"Sprint 3",IF(AND(K15>=DATE(2025,12,3),K15<=DATE(2025,12,16)),"Sprint 4",IF(AND(K15>=DATE(2025,12,17),K15<=DATE(2025,12,30)),"Sprint 5",IF(AND(K15>=DATE(2025,12,31),K15<=DATE(2026,1,20)),"Sprint 6","N/A")))))))) -> Sprint 3 | N15: =IF(K15="", "", (K15 - I15 +1)) -> 20 | O15: =IF(K15="","", IF(J15="", "N/A", IF(K15 > J15, "Late", IF(K15 < J15, "Early", IF(K15 = J15, "On time", ""))))) -> On time
A16: Before | B16: Committed | C16: Dev 2 | D16: Task | E16: P4 (Low) | F16: EXP-1437 | G16: Investigate delayed message processing in queue | H16: New | L16: =IF(K16="","",IF(AND(K16>=DATE(2025,10,21),K16<=DATE(2025,10,21)),"PI-3 Sprint 6",IF(AND(K16>=DATE(2025,10,22),K16<=DATE(2025,11,4)),"Sprint 1",IF(AND(K16>=DATE(2025,11,5),K16<=DATE(2025,11,18)),"Sprint 2",IF(AND(K16>=DATE(2025,11,19),K16<=DATE(2025,12,2)),"Sprint 3",IF(AND(K16>=DATE(2025,12,3),K16<=DATE(2025,12,16)),"Sprint 4",IF(AND(K16>=DATE(2025,12,17),K16<=DATE(2025,12,30)),"Sprint 5",IF(AND(K16>=DATE(2025,12,31),K16<=DATE(2026,1,20)),"Sprint 6","N/A")))))))) | N16: =IF(K16="", "", (K16 - I16 +1)) | O16: =IF(K16="","", IF(J16="", "N/A", IF(K16 > J16, "Late", IF(K16 < J16, "Early", IF(K16 = J16, "On time", "")))))
A17: Before | B17: Committed | C17: Dev 4 | D17: Support Task | E17: P2 (High) | F17: EXP-1462 | G17: Add retry logic to webhook handler | H17: Closed | I17: 45964 | J17: 45981 | K17: 45981 | L17: =IF(K17="","",IF(AND(K17>=DATE(2025,10,21),K17<=DATE(2025,10,21)),"PI-3 Sprint 6",IF(AND(K17>=DATE(2025,10,22),K17<=DATE(2025,11,4)),"Sprint 1",IF(AND(K17>=DATE(2025,11,5),K17<=DATE(2025,11,18)),"Sprint 2",IF(AND(K17>=DATE(2025,11,19),K17<=DATE(2025,12,2)),"Sprint 3",IF(AND(K17>=DATE(2025,12,3),K17<=DATE(2025,12,16)),"Sprint 4",IF(AND(K17>=DATE(2025,12,17),K17<=DATE(2025,12,30)),"Sprint 5",IF(AND(K17>=DATE(2025,12,31),K17<=DATE(2026,1,20)),"Sprint 6","N/A")))))))) -> Sprint 3 | N17: =IF(K17="", "", (K17 - I17 +1)) -> 18 | O17: =IF(K17="","", IF(J17="", "N/A", IF(K17 > J17, "Late", IF(K17 < J17, "Early", IF(K17 = J17, "On time", ""))))) -> On time
A18: Before | B18: Committed | C18: Dev 2 | D18: Task | E18: P3 (Med) | F18: EXP-1488 | G18: Update autoscaling thresholds for API service | H18: Closed | I18: 45965 | J18: 45973 | K18: 45973 | L18: =IF(K18="","",IF(AND(K18>=DATE(2025,10,21),K18<=DATE(2025,10,21)),"PI-3 Sprint 6",IF(AND(K18>=DATE(2025,10,22),K18<=DATE(2025,11,4)),"Sprint 1",IF(AND(K18>=DATE(2025,11,5),K18<=DATE(2025,11,18)),"Sprint 2",IF(AND(K18>=DATE(2025,11,19),K18<=DATE(2025,12,2)),"Sprint 3",IF(AND(K18>=DATE(2025,12,3),K18<=DATE(2025,12,16)),"Sprint 4",IF(AND(K18>=DATE(2025,12,17),K18<=DATE(2025,12,30)),"Sprint 5",IF(AND(K18>=DATE(2025,12,31),K18<=DATE(2026,1,20)),"Sprint 6","N/A")))))))) -> Sprint 2 | N18: =IF(K18="", "", (K18 - I18 +1)) -> 9 | O18: =IF(K18="","", IF(J18="", "N/A", IF(K18 > J18, "Late", IF(K18 < J18, "Early", IF(K18 = J18, "On time", ""))))) -> On time
A19: Before | B19: Committed | C19: Dev 5 | D19: Support Task | E19: P3 (Med) | F19: EXP-1514 | G19: Fix incorrect environment variable in prod | H19: Closed | I19: 45964 | J19: 45981 | K19: 45981 | L19: =IF(K19="","",IF(AND(K19>=DATE(2025,10,21),K19<=DATE(2025,10,21)),"PI-3 Sprint 6",IF(AND(K19>=DATE(2025,10,22),K19<=DATE(2025,11,4)),"Sprint 1",IF(AND(K19>=DATE(2025,11,5),K19<=DATE(2025,11,18)),"Sprint 2",IF(AND(K19>=DATE(2025,11,19),K19<=DATE(2025,12,2)),"Sprint 3",IF(AND(K19>=DATE(2025,12,3),K19<=DATE(2025,12,16)),"Sprint 4",IF(AND(K19>=DATE(2025,12,17),K19<=DATE(2025,12,30)),"Sprint 5",IF(AND(K19>=DATE(2025,12,31),K19<=DATE(2026,1,20)),"Sprint 6","N/A")))))))) -> Sprint 3 | N19: =IF(K19="", "", (K19 - I19 +1)) -> 18 | O19: =IF(K19="","", IF(J19="", "N/A", IF(K19 > J19, "Late", IF(K19 < J19, "Early", IF(K19 = J19, "On time", ""))))) -> On time
A20: Before | B20: Committed | C20: Dev 3 | D20: Support Task | E20: P1 (Critical) | F20: EXP-1541 | G20: Review and update deployment approval process | H20: New | L20: =IF(K20="","",IF(AND(K20>=DATE(2025,10,21),K20<=DATE(2025,10,21)),"PI-3 Sprint 6",IF(AND(K20>=DATE(2025,10,22),K20<=DATE(2025,11,4)),"Sprint 1",IF(AND(K20>=DATE(2025,11,5),K20<=DATE(2025,11,18)),"Sprint 2",IF(AND(K20>=DATE(2025,11,19),K20<=DATE(2025,12,2)),"Sprint 3",IF(AND(K20>=DATE(2025,12,3),K20<=DATE(2025,12,16)),"Sprint 4",IF(AND(K20>=DATE(2025,12,17),K20<=DATE(2025,12,30)),"Sprint 5",IF(AND(K20>=DATE(2025,12,31),K20<=DATE(2026,1,20)),"Sprint 6","N/A")))))))) | N20: =IF(K20="", "", (K20 - I20 +1)) | O20: =IF(K20="","", IF(J20="", "N/A", IF(K20 > J20, "Late", IF(K20 < J20, "Early", IF(K20 = J20, "On time", "")))))
A21: Before | B21: Committed | C21: Dev 1 | D21: Task | E21: P4 (Low) | F21: EXP-1569 | G21: Investigate missing logs from worker service | H21: Closed | I21: 45967 | J21: 45987 | K21: 45987 | L21: =IF(K21="","",IF(AND(K21>=DATE(2025,10,21),K21<=DATE(2025,10,21)),"PI-3 Sprint 6",IF(AND(K21>=DATE(2025,10,22),K21<=DATE(2025,11,4)),"Sprint 1",IF(AND(K21>=DATE(2025,11,5),K21<=DATE(2025,11,18)),"Sprint 2",IF(AND(K21>=DATE(2025,11,19),K21<=DATE(2025,12,2)),"Sprint 3",IF(AND(K21>=DATE(2025,12,3),K21<=DATE(2025,12,16)),"Sprint 4",IF(AND(K21>=DATE(2025,12,17),K21<=DATE(2025,12,30)),"Sprint 5",IF(AND(K21>=DATE(2025,12,31),K21<=DATE(2026,1,20)),"Sprint 6","N/A")))))))) -> Sprint 3 | N21: =IF(K21="", "", (K21 - I21 +1)) -> 21 | O21: =IF(K21="","", IF(J21="", "N/A", IF(K21 > J21, "Late", IF(K21 < J21, "Early", IF(K21 = J21, "On time", ""))))) -> On time
A22: Before | B22: Committed | C22: Dev 5 | D22: Task | E22: P2 (High) | F22: EXP-1593 | G22: Update monitoring dashboard for latency metrics | H22: Closed | I22: 45968 | J22: 45975 | K22: 45975 | L22: =IF(K22="","",IF(AND(K22>=DATE(2025,10,21),K22<=DATE(2025,10,21)),"PI-3 Sprint 6",IF(AND(K22>=DATE(2025,10,22),K22<=DATE(2025,11,4)),"Sprint 1",IF(AND(K22>=DATE(2025,11,5),K22<=DATE(2025,11,18)),"Sprint 2",IF(AND(K22>=DATE(2025,11,19),K22<=DATE(2025,12,2)),"Sprint 3",IF(AND(K22>=DATE(2025,12,3),K22<=DATE(2025,12,16)),"Sprint 4",IF(AND(K22>=DATE(2025,12,17),K22<=DATE(2025,12,30)),"Sprint 5",IF(AND(K22>=DATE(2025,12,31),K22<=DATE(2026,1,20)),"Sprint 6","N/A")))))))) -> Sprint 2 | N22: =IF(K22="", "", (K22 - I22 +1)) -> 8 | O22: =IF(K22="","", IF(J22="", "N/A", IF(K22 > J22, "Late", IF(K22 < J22, "Early", IF(K22 = J22, "On time", ""))))) -> On time
A23: Before | B23: Committed | C23: Dev 3 | D23: Task | E23: P1 (Critical) | F23: EXP-1620 | G23: Fix failed database migration in staging | H23: Closed | I23: 45955 | J23: 45965 | K23: 45965 | L23: =IF(K23="","",IF(AND(K23>=DATE(2025,10,21),K23<=DATE(2025,10,21)),"PI-3 Sprint 6",IF(AND(K23>=DATE(2025,10,22),K23<=DATE(2025,11,4)),"Sprint 1",IF(AND(K23>=DATE(2025,11,5),K23<=DATE(2025,11,18)),"Sprint 2",IF(AND(K23>=DATE(2025,11,19),K23<=DATE(2025,12,2)),"Sprint 3",IF(AND(K23>=DATE(2025,12,3),K23<=DATE(2025,12,16)),"Sprint 4",IF(AND(K23>=DATE(2025,12,17),K23<=DATE(2025,12,30)),"Sprint 5",IF(AND(K23>=DATE(2025,12,31),K23<=DATE(2026,1,20)),"Sprint 6","N/A")))))))) -> Sprint 1 | N23: =IF(K23="", "", (K23 - I23 +1)) -> 11 | O23: =IF(K23="","", IF(J23="", "N/A", IF(K23 > J23, "Late", IF(K23 < J23, "Early", IF(K23 = J23, "On time", ""))))) -> On time
A24: Before | B24: Committed | C24: Dev 1 | D24: Task | E24: P3 (Med) | F24: EXP-1648 | G24: Add health check endpoint to auth service | H24: New | L24: =IF(K24="","",IF(AND(K24>=DATE(2025,10,21),K24<=DATE(2025,10,21)),"PI-3 Sprint 6",IF(AND(K24>=DATE(2025,10,22),K24<=DATE(2025,11,4)),"Sprint 1",IF(AND(K24>=DATE(2025,11,5),K24<=DATE(2025,11,18)),"Sprint 2",IF(AND(K24>=DATE(2025,11,19),K24<=DATE(2025,12,2)),"Sprint 3",IF(AND(K24>=DATE(2025,12,3),K24<=DATE(2025,12,16)),"Sprint 4",IF(AND(K24>=DATE(2025,12,17),K24<=DATE(2025,12,30)),"Sprint 5",IF(AND(K24>=DATE(2025,12,31),K24<=DATE(2026,1,20)),"Sprint 6","N/A")))))))) | N24: =IF(K24="", "", (K24 - I24 +1)) | O24: =IF(K24="","", IF(J24="", "N/A", IF(K24 > J24, "Late", IF(K24 < J24, "Early", IF(K24 = J24, "On time", "")))))
A25: Before | B25: Committed | C25: Dev 2 | D25: Support Task | E25: P4 (Low) | F25: EXP-1675 | G25: Clean up deprecated IAM roles | H25: Closed | I25: 45969 | J25: 45969 | K25: 45969 | L25: =IF(K25="","",IF(AND(K25>=DATE(2025,10,21),K25<=DATE(2025,10,21)),"PI-3 Sprint 6",IF(AND(K25>=DATE(2025,10,22),K25<=DATE(2025,11,4)),"Sprint 1",IF(AND(K25>=DATE(2025,11,5),K25<=DATE(2025,11,18)),"Sprint 2",IF(AND(K25>=DATE(2025,11,19),K25<=DATE(2025,12,2)),"Sprint 3",IF(AND(K25>=DATE(2025,12,3),K25<=DATE(2025,12,16)),"Sprint 4",IF(AND(K25>=DATE(2025,12,17),K25<=DATE(2025,12,30)),"Sprint 5",IF(AND(K25>=DATE(2025,12,31),K25<=DATE(2026,1,20)),"Sprint 6","N/A")))))))) -> Sprint 2 | N25: =IF(K25="", "", (K25 - I25 +1)) -> 1 | O25: =IF(K25="","", IF(J25="", "N/A", IF(K25 > J25, "Late", IF(K25 < J25, "Early", IF(K25 = J25, "On time", ""))))) -> On time
A26: Before | B26: Committed | C26: Dev 4 | D26: Support Task | E26: P2 (High) | F26: EXP-1699 | G26: Investigate spike in 500 errors after release | H26: WIP | I26: 45967 | J26: 45987 | L26: =IF(K26="","",IF(AND(K26>=DATE(2025,10,21),K26<=DATE(2025,10,21)),"PI-3 Sprint 6",IF(AND(K26>=DATE(2025,10,22),K26<=DATE(2025,11,4)),"Sprint 1",IF(AND(K26>=DATE(2025,11,5),K26<=DATE(2025,11,18)),"Sprint 2",IF(AND(K26>=DATE(2025,11,19),K26<=DATE(2025,12,2)),"Sprint 3",IF(AND(K26>=DATE(2025,12,3),K26<=DATE(2025,12,16)),"Sprint 4",IF(AND(K26>=DATE(2025,12,17),K26<=DATE(2025,12,30)),"Sprint 5",IF(AND(K26>=DATE(2025,12,31),K26<=DATE(2026,1,20)),"Sprint 6","N/A")))))))) | N26: =IF(K26="", "", (K26 - I26 +1)) | O26: =IF(K26="","", IF(J26="", "N/A", IF(K26 > J26, "Late", IF(K26 < J26, "Early", IF(K26 = J26, "On time", "")))))
A27: Before | B27: Committed | C27: Dev 2 | D27: Task | E27: P3 (Med) | F27: EXP-1724 | G27: Update Helm chart values for prod | H27: WIP | I27: 45973 | J27: 45995 | L27: =IF(K27="","",IF(AND(K27>=DATE(2025,10,21),K27<=DATE(2025,10,21)),"PI-3 Sprint 6",IF(AND(K27>=DATE(2025,10,22),K27<=DATE(2025,11,4)),"Sprint 1",IF(AND(K27>=DATE(2025,11,5),K27<=DATE(2025,11,18)),"Sprint 2",IF(AND(K27>=DATE(2025,11,19),K27<=DATE(2025,12,2)),"Sprint 3",IF(AND(K27>=DATE(2025,12,3),K27<=DATE(2025,12,16)),"Sprint 4",IF(AND(K27>=DATE(2025,12,17),K27<=DATE(2025,12,30)),"Sprint 5",IF(AND(K27>=DATE(2025,12,31),K27<=DATE(2026,1,20)),"Sprint 6","N/A")))))))) | N27: =IF(K27="", "", (K27 - I27 +1)) | O27: =IF(K27="","", IF(J27="", "N/A", IF(K27 > J27, "Late", IF(K27 < J27, "Early", IF(K27 = J27, "On time", "")))))
A28: Before | B28: Committed | C28: Dev 1 | D28: Task | E28: P1 (Critical) | F28: EXP-1746 | G28: Fix cache invalidation issue | H28: New | L28: =IF(K28="","",IF(AND(K28>=DATE(2025,10,21),K28<=DATE(2025,10,21)),"PI-3 Sprint 6",IF(AND(K28>=DATE(2025,10,22),K28<=DATE(2025,11,4)),"Sprint 1",IF(AND(K28>=DATE(2025,11,5),K28<=DATE(2025,11,18)),"Sprint 2",IF(AND(K28>=DATE(2025,11,19),K28<=DATE(2025,12,2)),"Sprint 3",IF(AND(K28>=DATE(2025,12,3),K28<=DATE(2025,12,16)),"Sprint 4",IF(AND(K28>=DATE(2025,12,17),K28<=DATE(2025,12,30)),"Sprint 5",IF(AND(K28>=DATE(2025,12,31),K28<=DATE(2026,1,20)),"Sprint 6","N/A")))))))) | N28: =IF(K28="", "", (K28 - I28 +1)) | O28: =IF(K28="","", IF(J28="", "N/A", IF(K28 > J28, "Late", IF(K28 < J28, "Early", IF(K28 = J28, "On time", "")))))
A29: Before | B29: Committed | C29: Dev 5 | D29: Support Task | E29: P4 (Low) | F29: EXP-1778 | G29: Document on-call escalation procedure | H29: Closed | I29: 45975 | J29: 46000 | K29: 46000 | L29: =IF(K29="","",IF(AND(K29>=DATE(2025,10,21),K29<=DATE(2025,10,21)),"PI-3 Sprint 6",IF(AND(K29>=DATE(2025,10,22),K29<=DATE(2025,11,4)),"Sprint 1",IF(AND(K29>=DATE(2025,11,5),K29<=DATE(2025,11,18)),"Sprint 2",IF(AND(K29>=DATE(2025,11,19),K29<=DATE(2025,12,2)),"Sprint 3",IF(AND(K29>=DATE(2025,12,3),K29<=DATE(2025,12,16)),"Sprint 4",IF(AND(K29>=DATE(2025,12,17),K29<=DATE(2025,12,30)),"Sprint 5",IF(AND(K29>=DATE(2025,12,31),K29<=DATE(2026,1,20)),"Sprint 6","N/A")))))))) -> Sprint 4 | N29: =IF(K29="", "", (K29 - I29 +1)) -> 26 | O29: =IF(K29="","", IF(J29="", "N/A", IF(K29 > J29, "Late", IF(K29 < J29, "Early", IF(K29 = J29, "On time", ""))))) -> On time
A30: Before | B30: Committed | C30: Dev 4 | D30: Task | E30: P2 (High) | F30: EXP-1801 | G30: Investigate slow startup time for service | H30: Closed | I30: 45973 | J30: 45995 | K30: 45995 | L30: =IF(K30="","",IF(AND(K30>=DATE(2025,10,21),K30<=DATE(2025,10,21)),"PI-3 Sprint 6",IF(AND(K30>=DATE(2025,10,22),K30<=DATE(2025,11,4)),"Sprint 1",IF(AND(K30>=DATE(2025,11,5),K30<=DATE(2025,11,18)),"Sprint 2",IF(AND(K30>=DATE(2025,11,19),K30<=DATE(2025,12,2)),"Sprint 3",IF(AND(K30>=DATE(2025,12,3),K30<=DATE(2025,12,16)),"Sprint 4",IF(AND(K30>=DATE(2025,12,17),K30<=DATE(2025,12,30)),"Sprint 5",IF(AND(K30>=DATE(2025,12,31),K30<=DATE(2026,1,20)),"Sprint 6","N/A")))))))) -> Sprint 4 | N30: =IF(K30="", "", (K30 - I30 +1)) -> 23 | O30: =IF(K30="","", IF(J30="", "N/A", IF(K30 > J30, "Late", IF(K30 < J30, "Early", IF(K30 = J30, "On time", ""))))) -> On time
A31: After | B31: Uncommitted | C31: Dev 3 | D31: Task | E31: P3 (Med) | F31: EXP-1827 | G31: Add alert for disk space threshold | H31: WIP | I31: 45978 | J31: 46001 | L31: =IF(K31="","",IF(AND(K31>=DATE(2025,10,21),K31<=DATE(2025,10,21)),"PI-3 Sprint 6",IF(AND(K31>=DATE(2025,10,22),K31<=DATE(2025,11,4)),"Sprint 1",IF(AND(K31>=DATE(2025,11,5),K31<=DATE(2025,11,18)),"Sprint 2",IF(AND(K31>=DATE(2025,11,19),K31<=DATE(2025,12,2)),"Sprint 3",IF(AND(K31>=DATE(2025,12,3),K31<=DATE(2025,12,16)),"Sprint 4",IF(AND(K31>=DATE(2025,12,17),K31<=DATE(2025,12,30)),"Sprint 5",IF(AND(K31>=DATE(2025,12,31),K31<=DATE(2026,1,20)),"Sprint 6","N/A")))))))) | N31: =IF(K31="", "", (K31 - I31 +1)) | O31: =IF(K31="","", IF(J31="", "N/A", IF(K31 > J31, "Late", IF(K31 < J31, "Early", IF(K31 = J31, "On time", "")))))
A32: After | B32: Uncommitted | C32: Dev 4 | D32: Task | E32: P4 (Low) | F32: EXP-1852 | G32: Fix broken dependency in build pipeline | H32: New | L32: =IF(K32="","",IF(AND(K32>=DATE(2025,10,21),K32<=DATE(2025,10,21)),"PI-3 Sprint 6",IF(AND(K32>=DATE(2025,10,22),K32<=DATE(2025,11,4)),"Sprint 1",IF(AND(K32>=DATE(2025,11,5),K32<=DATE(2025,11,18)),"Sprint 2",IF(AND(K32>=DATE(2025,11,19),K32<=DATE(2025,12,2)),"Sprint 3",IF(AND(K32>=DATE(2025,12,3),K32<=DATE(2025,12,16)),"Sprint 4",IF(AND(K32>=DATE(2025,12,17),K32<=DATE(2025,12,30)),"Sprint 5",IF(AND(K32>=DATE(2025,12,31),K32<=DATE(2026,1,20)),"Sprint 6","N/A")))))))) | N32: =IF(K32="", "", (K32 - I32 +1)) | O32: =IF(K32="","", IF(J32="", "N/A", IF(K32 > J32, "Late", IF(K32 < J32, "Early", IF(K32 = J32, "On time", "")))))
A33: After | B33: Uncommitted | C33: Dev 5 | D33: Support Task | E33: P1 (Critical) | F33: EXP-1876 | G33: Update README for deployment repo | H33: Closed | I33: 45992 | J33: 46002 | K33: 46003 | L33: =IF(K33="","",IF(AND(K33>=DATE(2025,10,21),K33<=DATE(2025,10,21)),"PI-3 Sprint 6",IF(AND(K33>=DATE(2025,10,22),K33<=DATE(2025,11,4)),"Sprint 1",IF(AND(K33>=DATE(2025,11,5),K33<=DATE(2025,11,18)),"Sprint 2",IF(AND(K33>=DATE(2025,11,19),K33<=DATE(2025,12,2)),"Sprint 3",IF(AND(K33>=DATE(2025,12,3),K33<=DATE(2025,12,16)),"Sprint 4",IF(AND(K33>=DATE(2025,12,17),K33<=DATE(2025,12,30)),"Sprint 5",IF(AND(K33>=DATE(2025,12,31),K33<=DATE(2026,1,20)),"Sprint 6","N/A")))))))) -> Sprint 4 | N33: =IF(K33="", "", (K33 - I33 +1)) -> 12 | O33: =IF(K33="","", IF(J33="", "N/A", IF(K33 > J33, "Late", IF(K33 < J33, "Early", IF(K33 = J33, "On time", ""))))) -> Late
A34: After | B34: Uncommitted | C34: Dev 3 | D34: Task | E34: P2 (High) | F34: EXP-1904 | G34: Investigate failed scheduled job | H34: WIP | I34: 45980 | J34: 46003 | L34: =IF(K34="","",IF(AND(K34>=DATE(2025,10,21),K34<=DATE(2025,10,21)),"PI-3 Sprint 6",IF(AND(K34>=DATE(2025,10,22),K34<=DATE(2025,11,4)),"Sprint 1",IF(AND(K34>=DATE(2025,11,5),K34<=DATE(2025,11,18)),"Sprint 2",IF(AND(K34>=DATE(2025,11,19),K34<=DATE(2025,12,2)),"Sprint 3",IF(AND(K34>=DATE(2025,12,3),K34<=DATE(2025,12,16)),"Sprint 4",IF(AND(K34>=DATE(2025,12,17),K34<=DATE(2025,12,30)),"Sprint 5",IF(AND(K34>=DATE(2025,12,31),K34<=DATE(2026,1,20)),"Sprint 6","N/A")))))))) | N34: =IF(K34="", "", (K34 - I34 +1)) | O34: =IF(K34="","", IF(J34="", "N/A", IF(K34 > J34, "Late", IF(K34 < J34, "Early", IF(K34 = J34, "On time", "")))))
A35: After | B35: Uncommitted | C35: Dev 5 | D35: Task | E35: P3 (Med) | F35: EXP-1931 | G35: Fix typo in environment configuration | H35: New | L35: =IF(K35="","",IF(AND(K35>=DATE(2025,10,21),K35<=DATE(2025,10,21)),"PI-3 Sprint 6",IF(AND(K35>=DATE(2025,10,22),K35<=DATE(2025,11,4)),"Sprint 1",IF(AND(K35>=DATE(2025,11,5),K35<=DATE(2025,11,18)),"Sprint 2",IF(AND(K35>=DATE(2025,11,19),K35<=DATE(2025,12,2)),"Sprint 3",IF(AND(K35>=DATE(2025,12,3),K35<=DATE(2025,12,16)),"Sprint 4",IF(AND(K35>=DATE(2025,12,17),K35<=DATE(2025,12,30)),"Sprint 5",IF(AND(K35>=DATE(2025,12,31),K35<=DATE(2026,1,20)),"Sprint 6","N/A")))))))) | N35: =IF(K35="", "", (K35 - I35 +1)) | O35: =IF(K35="","", IF(J35="", "N/A", IF(K35 > J35, "Late", IF(K35 < J35, "Early", IF(K35 = J35, "On time", "")))))
A36: After | B36: Uncommitted | C36: Dev 1 | D36: Support Task | E36: P4 (Low) | F36: EXP-1959 | G36: Update secret rotation schedule | H36: WIP | I36: 45980 | J36: 46003 | L36: =IF(K36="","",IF(AND(K36>=DATE(2025,10,21),K36<=DATE(2025,10,21)),"PI-3 Sprint 6",IF(AND(K36>=DATE(2025,10,22),K36<=DATE(2025,11,4)),"Sprint 1",IF(AND(K36>=DATE(2025,11,5),K36<=DATE(2025,11,18)),"Sprint 2",IF(AND(K36>=DATE(2025,11,19),K36<=DATE(2025,12,2)),"Sprint 3",IF(AND(K36>=DATE(2025,12,3),K36<=DATE(2025,12,16)),"Sprint 4",IF(AND(K36>=DATE(2025,12,17),K36<=DATE(2025,12,30)),"Sprint 5",IF(AND(K36>=DATE(2025,12,31),K36<=DATE(2026,1,20)),"Sprint 6","N/A")))))))) | N36: =IF(K36="", "", (K36 - I36 +1)) | O36: =IF(K36="","", IF(J36="", "N/A", IF(K36 > J36, "Late", IF(K36 < J36, "Early", IF(K36 = J36, "On time", "")))))
A37: After | B37: Uncommitted | C37: Dev 2 | D37: Support Task | E37: P2 (High) | F37: EXP-1983 | G37: Investigate dropped events in analytics pipeline | H37: Closed | I37: 45993 | J37: 46007 | K37: 46007 | L37: =IF(K37="","",IF(AND(K37>=DATE(2025,10,21),K37<=DATE(2025,10,21)),"PI-3 Sprint 6",IF(AND(K37>=DATE(2025,10,22),K37<=DATE(2025,11,4)),"Sprint 1",IF(AND(K37>=DATE(2025,11,5),K37<=DATE(2025,11,18)),"Sprint 2",IF(AND(K37>=DATE(2025,11,19),K37<=DATE(2025,12,2)),"Sprint 3",IF(AND(K37>=DATE(2025,12,3),K37<=DATE(2025,12,16)),"Sprint 4",IF(AND(K37>=DATE(2025,12,17),K37<=DATE(2025,12,30)),"Sprint 5",IF(AND(K37>=DATE(2025,12,31),K37<=DATE(2026,1,20)),"Sprint 6","N/A")))))))) -> Sprint 4 | N37: =IF(K37="", "", (K37 - I37 +1)) -> 15 | O37: =IF(K37="","", IF(J37="", "N/A", IF(K37 > J37, "Late", IF(K37 < J37, "Early", IF(K37 = J37, "On time", ""))))) -> On time
A38: After | B38: Uncommitted | C38: Dev 4 | D38: Task | E38: P1 (Critical) | F38: EXP-2010 | G38: Add timeout configuration to external API calls | H38: WIP | I38: 45985 | J38: 46008 | L38: =IF(K38="","",IF(AND(K38>=DATE(2025,10,21),K38<=DATE(2025,10,21)),"PI-3 Sprint 6",IF(AND(K38>=DATE(2025,10,22),K38<=DATE(2025,11,4)),"Sprint 1",IF(AND(K38>=DATE(2025,11,5),K38<=DATE(2025,11,18)),"Sprint 2",IF(AND(K38>=DATE(2025,11,19),K38<=DATE(2025,12,2)),"Sprint 3",IF(AND(K38>=DATE(2025,12,3),K38<=DATE(2025,12,16)),"Sprint 4",IF(AND(K38>=DATE(2025,12,17),K38<=DATE(2025,12,30)),"Sprint 5",IF(AND(K38>=DATE(2025,12,31),K38<=DATE(2026,1,20)),"Sprint 6","N/A")))))))) | N38: =IF(K38="", "", (K38 - I38 +1)) | O38: =IF(K38="","", IF(J38="", "N/A", IF(K38 > J38, "Late", IF(K38 < J38, "Early", IF(K38 = J38, "On time", "")))))
A39: After | B39: Uncommitted | C39: Dev 2 | D39: Support Task | E39: P3 (Med) | F39: EXP-2036 | G39: Fix misconfigured load balancer rule | H39: New | L39: =IF(K39="","",IF(AND(K39>=DATE(2025,10,21),K39<=DATE(2025,10,21)),"PI-3 Sprint 6",IF(AND(K39>=DATE(2025,10,22),K39<=DATE(2025,11,4)),"Sprint 1",IF(AND(K39>=DATE(2025,11,5),K39<=DATE(2025,11,18)),"Sprint 2",IF(AND(K39>=DATE(2025,11,19),K39<=DATE(2025,12,2)),"Sprint 3",IF(AND(K39>=DATE(2025,12,3),K39<=DATE(2025,12,16)),"Sprint 4",IF(AND(K39>=DATE(2025,12,17),K39<=DATE(2025,12,30)),"Sprint 5",IF(AND(K39>=DATE(2025,12,31),K39<=DATE(2026,1,20)),"Sprint 6","N/A")))))))) | N39: =IF(K39="", "", (K39 - I39 +1)) | O39: =IF(K39="","", IF(J39="", "N/A", IF(K39 > J39, "Late", IF(K39 < J39, "Early", IF(K39 = J39, "On time", "")))))
A40: After | B40: Uncommitted | C40: Dev 4 | D40: Task | E40: P4 (Low) | F40: EXP-2064 | G40: Update incident postmortem template | H40: Closed | I40: 46003 | J40: 46007 | K40: 46007 | L40: =IF(K40="","",IF(AND(K40>=DATE(2025,10,21),K40<=DATE(2025,10,21)),"PI-3 Sprint 6",IF(AND(K40>=DATE(2025,10,22),K40<=DATE(2025,11,4)),"Sprint 1",IF(AND(K40>=DATE(2025,11,5),K40<=DATE(2025,11,18)),"Sprint 2",IF(AND(K40>=DATE(2025,11,19),K40<=DATE(2025,12,2)),"Sprint 3",IF(AND(K40>=DATE(2025,12,3),K40<=DATE(2025,12,16)),"Sprint 4",IF(AND(K40>=DATE(2025,12,17),K40<=DATE(2025,12,30)),"Sprint 5",IF(AND(K40>=DATE(2025,12,31),K40<=DATE(2026,1,20)),"Sprint 6","N/A")))))))) -> Sprint 4 | N40: =IF(K40="", "", (K40 - I40 +1)) -> 5 | O40: =IF(K40="","", IF(J40="", "N/A", IF(K40 > J40, "Late", IF(K40 < J40, "Early", IF(K40 = J40, "On time", ""))))) -> On time
...

Sheet Kanban_Metrics
A1: Entire Team Metrics | D1: Throughput (Tasks closed within time Period) | H1: By Team Member
A2: Average Cycle Time (Days) | B2: =AVERAGE(I3:I7) -> 12.60066 | D2: Sprint 1 (Oct. 22 - Nov. 4) | E2: =COUNTIFS(Raw_Ticket_Data!H$2:H$200, "Closed", Raw_Ticket_Data!L$2:L$200, "Sprint 1") -> 7 | H2: Developer | I2: Avg. Cycle Time (DAYS) | J2: Current WIP | K2: Closed PI Tickets
A3: Current WIP | B3: =COUNTIF(Raw_Ticket_Data!H2:H200, "WIP") -> 22 | D3: Sprint 2 (Nov. 5 - Nov. 18) | E3: =COUNTIFS(Raw_Ticket_Data!H$2:H$200, "Closed", Raw_Ticket_Data!L$2:L$200, "Sprint 2") -> 6 | H3: Dev 1 | I3: =AVERAGEIFS(Raw_Ticket_Data!N:N, Raw_Ticket_Data!C:C, "Dev 1") -> 9.7777778 | J3: =COUNTIFS(Raw_Ticket_Data!$C:$C, "Dev 1",Raw_Ticket_Data!$H:$H, "WIP") -> 5 | K3: =COUNTIFS(Raw_Ticket_Data!$C:$C, "Dev 1",Raw_Ticket_Data!$H:$H, "Closed") -> 9
A4: Current Closed | B4: =COUNTIF(Raw_Ticket_Data!H2:H200, "Closed") -> 50 | D4: Sprint 3 (Nov. 19 - Dec. 2) | E4: =COUNTIFS(Raw_Ticket_Data!H$2:H$200, "Closed", Raw_Ticket_Data!L$2:L$200, "Sprint 3") -> 9 | H4: Dev 2 | I4: =AVERAGEIFS(Raw_Ticket_Data!N:N, Raw_Ticket_Data!C:C, "Dev 2") -> 11.090909 | J4: =COUNTIFS(Raw_Ticket_Data!$C:$C, "Dev 2",Raw_Ticket_Data!$H:$H, "WIP") -> 3 | K4: =COUNTIFS(Raw_Ticket_Data!$C:$C, "Dev 2",Raw_Ticket_Data!$H:$H, "Closed") -> 11
A5: Current On Hold | B5: =COUNTIF(Raw_Ticket_Data!H2:H200, "On Hold") -> 2 | D5: Sprint 4 (Dec. 3 - Dec. 16) | E5: =COUNTIFS(Raw_Ticket_Data!H$2:H$200, "Closed", Raw_Ticket_Data!L$2:L$200, "Sprint 4") -> 11 | H5: Dev 3 | I5: =AVERAGEIFS(Raw_Ticket_Data!N:N, Raw_Ticket_Data!C:C, "Dev 3") -> 12.333333 | J5: =COUNTIFS(Raw_Ticket_Data!$C:$C, "Dev 3",Raw_Ticket_Data!$H:$H, "WIP") -> 5 | K5: =COUNTIFS(Raw_Ticket_Data!$C:$C, "Dev 3",Raw_Ticket_Data!$H:$H, "Closed") -> 6
A6: Current Open/New | B6: =COUNTIF(Raw_Ticket_Data!H2:H200, "New") -> 24 | D6: Sprint 5 (Dec. 17 - Dec. 30) | E6: =COUNTIFS(Raw_Ticket_Data!H$2:H$200, "Closed", Raw_Ticket_Data!L$2:L$200, "Sprint 5") -> 6 | H6: Dev 4 | I6: =AVERAGEIFS(Raw_Ticket_Data!N:N, Raw_Ticket_Data!C:C, "Dev 4") -> 13.416667 | J6: =COUNTIFS(Raw_Ticket_Data!$C:$C, "Dev 4",Raw_Ticket_Data!$H:$H, "WIP") -> 5 | K6: =COUNTIFS(Raw_Ticket_Data!$C:$C, "Dev 4",Raw_Ticket_Data!$H:$H, "Closed") -> 11
A7: Cancelled | B7: =COUNTIF(Raw_Ticket_Data!H2:H200, "Cancelled") -> 1 | D7: Sprint 6 (Dec. 31 - Jan 20) | E7: =COUNTIFS(Raw_Ticket_Data!H$2:H$200, "Closed", Raw_Ticket_Data!L$2:L$200, "Sprint 6") -> 11 | H7: Dev 5 | I7: =AVERAGEIFS(Raw_Ticket_Data!N:N, Raw_Ticket_Data!C:C, "Dev 5") -> 16.384615 | J7: =COUNTIFS(Raw_Ticket_Data!$C:$C, "Dev 5",Raw_Ticket_Data!$H:$H, "WIP") -> 4 | K7: =COUNTIFS(Raw_Ticket_Data!$C:$C, "Dev 5",Raw_Ticket_Data!$H:$H, "Closed") -> 13
A9: ETA Forecast Accuracy
A10: On time | B10: =COUNTIF(Raw_Ticket_Data!O$2:O$200, "On time") -> 39
A11: Early | B11: =COUNTIF(Raw_Ticket_Data!O$2:O$200, "EARLY") -> 6
A12: Late | B12: =COUNTIF(Raw_Ticket_Data!O$2:O$200, "LATE") -> 6
A13: No ETA Given | B13: =COUNTIF(Raw_Ticket_Data!O$2:O$200, "N/A") -> 0

Sheet Delivery_Dashboard
A1: Issue Details | B1: Priority | C1: Total | D1: Open | E1: WIP | F1: On Hold | G1: Closed
A2: Total Number of Tasks Planned in PI-4 | B2: P1 | C2: =SUM(D2:G2) -> 4 | D2: =COUNTIFS(Raw_Ticket_Data!$D:$D, "TASK", Raw_Ticket_Data!$A:$A, "BEFORE", Raw_Ticket_Data!$B:$B, "COMMITTED", Raw_Ticket_Data!$E:$E, "P1 (Critical)", Raw_Ticket_Data!$H:$H, "NEW") -> 2 | E2: =COUNTIFS(Raw_Ticket_Data!$D:$D, "TASK", Raw_Ticket_Data!$A:$A, "BEFORE", Raw_Ticket_Data!$B:$B, "COMMITTED", Raw_Ticket_Data!$E:$E, "P1 (Critical)", Raw_Ticket_Data!$H:$H, "WIP") -> 0 | F2: =COUNTIFS(Raw_Ticket_Data!$D:$D, "TASK", Raw_Ticket_Data!$A:$A, "BEFORE", Raw_Ticket_Data!$B:$B, "COMMITTED", Raw_Ticket_Data!$E:$E, "P1 (Critical)", Raw_Ticket_Data!$H:$H, "On Hold") -> 0 | G2: =COUNTIFS(Raw_Ticket_Data!$D:$D, "TASK", Raw_Ticket_Data!$A:$A, "BEFORE", Raw_Ticket_Data!$B:$B, "COMMITTED", Raw_Ticket_Data!$E:$E, "P1 (Critical)", Raw_Ticket_Data!$H:$H, "Closed") -> 2
B3: P2 | C3: =SUM(D3:G3) -> 4 | D3: =COUNTIFS(Raw_Ticket_Data!$D:$D, "TASK", Raw_Ticket_Data!$A:$A, "BEFORE", Raw_Ticket_Data!$B:$B, "COMMITTED", Raw_Ticket_Data!$E:$E, "P2 (High)", Raw_Ticket_Data!$H:$H, "NEW") -> 0 | E3: =COUNTIFS(Raw_Ticket_Data!$D:$D, "TASK", Raw_Ticket_Data!$A:$A, "BEFORE", Raw_Ticket_Data!$B:$B, "COMMITTED", Raw_Ticket_Data!$E:$E, "P2 (High)", Raw_Ticket_Data!$H:$H, "WIP") -> 0 | F3: =COUNTIFS(Raw_Ticket_Data!$D:$D, "TASK", Raw_Ticket_Data!$A:$A, "BEFORE", Raw_Ticket_Data!$B:$B, "COMMITTED", Raw_Ticket_Data!$E:$E, "P2 (High)", Raw_Ticket_Data!$H:$H, "On Hold") -> 1 | G3: =COUNTIFS(Raw_Ticket_Data!$D:$D, "TASK", Raw_Ticket_Data!$A:$A, "BEFORE", Raw_Ticket_Data!$B:$B, "COMMITTED", Raw_Ticket_Data!$E:$E, "P2 (High)", Raw_Ticket_Data!$H:$H, "Closed") -> 3
B4: P3 | C4: =SUM(D4:G4) -> 6 | D4: =COUNTIFS(Raw_Ticket_Data!$D:$D, "TASK", Raw_Ticket_Data!$A:$A, "BEFORE", Raw_Ticket_Data!$B:$B, "COMMITTED", Raw_Ticket_Data!$E:$E, "P3 (Med)", Raw_Ticket_Data!$H:$H, "NEW") -> 2 | E4: =COUNTIFS(Raw_Ticket_Data!$D:$D, "TASK", Raw_Ticket_Data!$A:$A, "BEFORE", Raw_Ticket_Data!$B:$B, "COMMITTED", Raw_Ticket_Data!$E:$E, "P3 (Med)", Raw_Ticket_Data!$H:$H, "WIP") -> 1 | F4: =COUNTIFS(Raw_Ticket_Data!$D:$D, "TASK", Raw_Ticket_Data!$A:$A, "BEFORE", Raw_Ticket_Data!$B:$B, "COMMITTED", Raw_Ticket_Data!$E:$E, "P3 (med)", Raw_Ticket_Data!$H:$H, "On Hold") -> 0 | G4: =COUNTIFS(Raw_Ticket_Data!$D:$D, "TASK", Raw_Ticket_Data!$A:$A, "BEFORE", Raw_Ticket_Data!$B:$B, "COMMITTED", Raw_Ticket_Data!$E:$E, "P3 (med)", Raw_Ticket_Data!$H:$H, "Closed") -> 3
B5: P4 | C5: =SUM(D5:G5) -> 5 | D5: =COUNTIFS(Raw_Ticket_Data!$D:$D, "TASK", Raw_Ticket_Data!$A:$A, "BEFORE", Raw_Ticket_Data!$B:$B, "COMMITTED", Raw_Ticket_Data!$E:$E, "P4 (Low)", Raw_Ticket_Data!$H:$H, "NEW") -> 1 | E5: =COUNTIFS(Raw_Ticket_Data!$D:$D, "TASK", Raw_Ticket_Data!$A:$A, "BEFORE", Raw_Ticket_Data!$B:$B, "COMMITTED", Raw_Ticket_Data!$E:$E, "P4 (Low)", Raw_Ticket_Data!$H:$H, "WIP") -> 0 | F5: =COUNTIFS(Raw_Ticket_Data!$D:$D, "TASK", Raw_Ticket_Data!$A:$A, "BEFORE", Raw_Ticket_Data!$B:$B, "COMMITTED", Raw_Ticket_Data!$E:$E, "P4 (Low)", Raw_Ticket_Data!$H:$H, "On Hold") -> 0 | G5: =COUNTIFS(Raw_Ticket_Data!$D:$D, "TASK", Raw_Ticket_Data!$A:$A, "BEFORE", Raw_Ticket_Data!$B:$B, "COMMITTED", Raw_Ticket_Data!$E:$E, "P4 (Low)", Raw_Ticket_Data!$H:$H, "Closed") -> 4
B6: Total | C6: =SUM(D6:G6) -> 19 | D6: =SUM(D2:D5) -> 5 | E6: =SUM(E2:E5) -> 1 | F6: =SUM(F2:F5) -> 1 | G6: =SUM(G2:G5) -> 12
A8: Number of Issues created AFTER planning | B8: P1 | C8: =SUM(D8:G8) -> 8 | D8: =COUNTIFS(Raw_Ticket_Data!$D:$D, "TASK", Raw_Ticket_Data!$A:$A, "After", Raw_Ticket_Data!$B:$B, "Uncommitted", Raw_Ticket_Data!$E:$E, "P1 (Critical)", Raw_Ticket_Data!$H:$H, "NEW") -> 3 | E8: =COUNTIFS(Raw_Ticket_Data!$D:$D, "TASK", Raw_Ticket_Data!$A:$A, "After", Raw_Ticket_Data!$B:$B, "Uncommitted", Raw_Ticket_Data!$E:$E, "P1 (Critical)", Raw_Ticket_Data!$H:$H, "WIP") -> 4 | F8: =COUNTIFS(Raw_Ticket_Data!$D:$D, "TASK", Raw_Ticket_Data!$A:$A, "After", Raw_Ticket_Data!$B:$B, "Uncommitted", Raw_Ticket_Data!$E:$E, "P1 (Critical)", Raw_Ticket_Data!$H:$H, "On Hold") -> 0 | G8: =COUNTIFS(Raw_Ticket_Data!$D:$D, "TASK", Raw_Ticket_Data!$A:$A, "After", Raw_Ticket_Data!$B:$B, "Uncommitted", Raw_Ticket_Data!$E:$E, "P1 (Critical)", Raw_Ticket_Data!$H:$H, "Closed") -> 1
B9: P2 | C9: =SUM(D9:G9) -> 15 | D9: =COUNTIFS(Raw_Ticket_Data!$D:$D, "TASK", Raw_Ticket_Data!$A:$A, "After", Raw_Ticket_Data!$B:$B, "Uncommitted", Raw_Ticket_Data!$E:$E, "P2 (High)", Raw_Ticket_Data!$H:$H, "NEW") -> 0 | E9: =COUNTIFS(Raw_Ticket_Data!$D:$D, "TASK", Raw_Ticket_Data!$A:$A, "After", Raw_Ticket_Data!$B:$B, "Uncommitted", Raw_Ticket_Data!$E:$E, "P2 (High)", Raw_Ticket_Data!$H:$H, "WIP") -> 3 | F9: =COUNTIFS(Raw_Ticket_Data!$D:$D, "TASK", Raw_Ticket_Data!$A:$A, "After", Raw_Ticket_Data!$B:$B, "Uncommitted", Raw_Ticket_Data!$E:$E, "P2 (High)", Raw_Ticket_Data!$H:$H, "On Hold") -> 0 | G9: =COUNTIFS(Raw_Ticket_Data!$D:$D, "TASK", Raw_Ticket_Data!$A:$A, "After", Raw_Ticket_Data!$B:$B, "Uncommitted", Raw_Ticket_Data!$E:$E, "P2 (High)", Raw_Ticket_Data!$H:$H, "Closed") -> 12
B10: P3 | C10: =SUM(D10:G10) -> 12 | D10: =COUNTIFS(Raw_Ticket_Data!$D:$D, "TASK", Raw_Ticket_Data!$A:$A, "After", Raw_Ticket_Data!$B:$B, "Uncommitted", Raw_Ticket_Data!$E:$E, "P3 (Med)", Raw_Ticket_Data!$H:$H, "NEW") -> 2 | E10: =COUNTIFS(Raw_Ticket_Data!$D:$D, "TASK", Raw_Ticket_Data!$A:$A, "After", Raw_Ticket_Data!$B:$B, "Uncommitted", Raw_Ticket_Data!$E:$E, "P3 (Med)", Raw_Ticket_Data!$H:$H, "WIP") -> 7 | F10: =COUNTIFS(Raw_Ticket_Data!$D:$D, "TASK", Raw_Ticket_Data!$A:$A, "After", Raw_Ticket_Data!$B:$B, "Uncommitted", Raw_Ticket_Data!$E:$E, "P3 (med)", Raw_Ticket_Data!$H:$H, "On Hold") -> 0 | G10: =COUNTIFS(Raw_Ticket_Data!$D:$D, "TASK", Raw_Ticket_Data!$A:$A, "After", Raw_Ticket_Data!$B:$B, "Uncommitted", Raw_Ticket_Data!$E:$E, "P3 (med)", Raw_Ticket_Data!$H:$H, "Closed") -> 3
B11: P4 | C11: =SUM(D11:G11) -> 10 | D11: =COUNTIFS(Raw_Ticket_Data!$D:$D, "TASK", Raw_Ticket_Data!$A:$A, "After", Raw_Ticket_Data!$B:$B, "Uncommitted", Raw_Ticket_Data!$E:$E, "P4 (Low)", Raw_Ticket_Data!$H:$H, "NEW") -> 7 | E11: =COUNTIFS(Raw_Ticket_Data!$D:$D, "TASK", Raw_Ticket_Data!$A:$A, "After", Raw_Ticket_Data!$B:$B, "Uncommitted", Raw_Ticket_Data!$E:$E, "P4 (Low)", Raw_Ticket_Data!$H:$H, "WIP") -> 0 | F11: =COUNTIFS(Raw_Ticket_Data!$D:$D, "TASK", Raw_Ticket_Data!$A:$A, "After", Raw_Ticket_Data!$B:$B, "Uncommitted", Raw_Ticket_Data!$E:$E, "P4 (Low)", Raw_Ticket_Data!$H:$H, "On Hold") -> 0 | G11: =COUNTIFS(Raw_Ticket_Data!$D:$D, "TASK", Raw_Ticket_Data!$A:$A, "After", Raw_Ticket_Data!$B:$B, "Uncommitted", Raw_Ticket_Data!$E:$E, "P4 (Low)", Raw_Ticket_Data!$H:$H, "Closed") -> 3
B12: Total | C12: =SUM(C8:C11) -> 45 | D12: =SUM(D8:D11) -> 12 | E12: =SUM(E8:E11) -> 14 | F12: =SUM(F8:F11) -> 0 | G12: =SUM(G8:G11) -> 19
A14: Total Number of Support Tasks | B14: Total | C14: =SUM(D14:G14) -> 33 | D14: =COUNTIFS(Raw_Ticket_Data!$D:$D, "Support Task", Raw_Ticket_Data!$H:$H, "New") -> 7 | E14: =COUNTIFS(Raw_Ticket_Data!$D:$D, "Support Task", Raw_Ticket_Data!$H:$H, "WIP") -> 7 | F14: =COUNTIFS(Raw_Ticket_Data!$D:$D, "Support Task", Raw_Ticket_Data!$H:$H, "On Hold") -> 1 | G14: =COUNTIFS(Raw_Ticket_Data!$D:$D, "Support Task", Raw_Ticket_Data!$H:$H, "Closed") -> 18
B17: Planned Tasks (bar chart)
C18: =D1 -> Open | D18: =E1 -> WIP | E18: =F1 -> On Hold | F18: =G1 -> Closed
B19: P1 | C19: =D2 -> 2 | D19: =E2 -> 0 | E19: =F2 -> 0 | F19: =G2 -> 2
B20: P2 | C20: =D3 -> 0 | D20: =E3 -> 0 | E20: =F3 -> 1 | F20: =G3 -> 3
B21: P3 | C21: =D4 -> 2 | D21: =E4 -> 1 | E21: =F4 -> 0 | F21: =G4 -> 3
B22: P4 | C22: =D5 -> 1 | D22: =E5 -> 0 | E22: =F5 -> 0 | F22: =G5 -> 4
B23: Unplanned Tasks (bar chart)
C24: Open | D24: WIP | E24: On Hold | F24: Closed
B25: P1 | C25: =D8 -> 3 | D25: =E8 -> 4 | E25: =F8 -> 0 | F25: =G8 -> 1
B26: P2 | C26: =D9 -> 0 | D26: =E9 -> 3 | E26: =F9 -> 0 | F26: =G9 -> 12
B27: P3 | C27: =D10 -> 2 | D27: =E10 -> 7 | E27: =F10 -> 0 | F27: =G10 -> 3
B28: P4 | C28: =D11 -> 7 | D28: =E11 -> 0 | E28: =F11 -> 0 | F28: =G11 -> 3
E30: Cycle Time Trend Over Time
B31: Throughput By Sprint | E31: Sprint | G31: Avg Cycle Time
B32: Sprint 1 | C32: =Kanban_Metrics!E2 -> 7 | E32: Sprint 1 | G32: =AVERAGEIFS( Raw_Ticket_Data!N:N, Raw_Ticket_Data!H:H, "Closed", Raw_Ticket_Data!L:L, "Sprint 1" ) -> 9.1428571
B33: Sprint 2 | C33: =Kanban_Metrics!E3 -> 6 | E33: Sprint 2 | G33: =AVERAGEIFS( Raw_Ticket_Data!N:N, Raw_Ticket_Data!H:H, "Closed", Raw_Ticket_Data!L:L, "Sprint 2" ) -> 11
B34: Sprint 3 | C34: =Kanban_Metrics!E4 -> 9 | E34: Sprint 3 | G34: =AVERAGEIFS( Raw_Ticket_Data!N:N, Raw_Ticket_Data!H:H, "Closed", Raw_Ticket_Data!L:L, "Sprint 3" ) -> 14.333333
B35: Sprint 4 | C35: =Kanban_Metrics!E5 -> 11 | E35: Sprint 4 | G35: =AVERAGEIFS( Raw_Ticket_Data!N:N, Raw_Ticket_Data!H:H, "Closed", Raw_Ticket_Data!L:L, "Sprint 4" ) -> 13.090909
B36: Sprint 5 | C36: =Kanban_Metrics!E6 -> 6 | E36: Sprint 5 | G36: =AVERAGEIFS( Raw_Ticket_Data!N:N, Raw_Ticket_Data!H:H, "Closed", Raw_Ticket_Data!L:L, "Sprint 5" ) -> 14.333333
B37: Sprint 6 | C37: =Kanban_Metrics!E7 -> 11 | E37: Sprint 6 | G37: =AVERAGEIFS( Raw_Ticket_Data!N:N, Raw_Ticket_Data!H:H, "Closed", Raw_Ticket_Data!L:L, "Sprint 6" ) -> 14

Sheet Insights & Observations
A1: Kanban Delivery Analytics Dashboard
A3: Excel | Data Modeling | Flow Metrics
A4: Insights below are based on sample Kanban ticket data and are intended to demonstrate analytical interpretation rather than reflect a real team’s performance.
A7: Insight | E7: Analysis
A8: Cycle Time Trends | E8: Based on the cycle time trend, cycle time remained stable across most sprints, with the lowest average cycle time observed in Sprint 1. Reviewing ticket mix and WIP levels during Sprint 1 may help identify practices that contributed to faster delivery and could be replicated in future sprints.
A10: Status Distribution | E10: Closed and In Progress tickets make up the majority of work, indicating steady throughput across the PI. A small number of On Hold items suggests limited external blockers. However, periodic review of these tickets may help prevent long-running stagnation.
A12: Planned vs. Unplanned Work | E12: The Planned vs Unplanned bar chart shows that unplanned work represents a consistent portion of total delivery, reducing planned capacity each sprint. This pattern highlights the importance of reserving buffer capacity during PI planning to maintain delivery predictability.
A14: Priority Mix | E14: Most completed tickets fall within Medium and High priority levels, with few Critical items observed. This suggests effective prioritization and minimal reactive work, allowing the team to focus on planned delivery rather than urgent interruptions.

Sheet README
A1: Kanban Delivery Analytics Dashboard
A2: Excel | Data Modeling | Flow Metrics
A4: Project Overview:
A5: This dashboard is inspired by a real-world Kanban reporting solution I designed while supporting a DevOps team. For this project, I recreated the structure using synthetic data to focus on metric design, data modeling, and visualization best practices. The dashboard highlights workflow trends, delivery performance, and operational insights intended to support continuous improvement and stakeholder communication.
A6: Business Problem:
A7: Kanban teams often struggle to maintain visibility into work in progress, delivery predictability, and flow efficiency. Leadership typically requires clear, concise metrics to understand progress without disrupting team workflows.
A9: Project Objectives:
A10: > Track work status and flow using Kanban metrics > Analyze cycle time trends across sprints > Compare planned vs unplanned work > Provide clear, executive-friendly visualizations
A11: Data Description:
A12: The dataset consists of 99 synthetic Kanban tickets modeled after a DevOps team workflow. Each ticket includes key attributes used to analyze flow and delivery performance. Key fields include: > Status (New, WIP, Closed, On Hold, Cancelled) > Priority (P1-P4) > Sprint (Sprint 1-6) > Start Date, ETA, Close Date > Calculated Cycle Time
A13: Metrics & Calculations
A14: Key metrics were calculated using Excel formulas and include cycle time, throughput, forecast accuracy, and planned vs. unplanned work distribution.
... A23: > Microsoft Excel > Tables and Charts > Excel Formulas (AVERAGEIFS, COUNTIFS, etc.)
